Traceback (most recent call last):
  File "/opt/hostedtoolcache/Python/3.10.18/x64/lib/python3.10/site-packages/jupyter_cache/executors/utils.py", line 58, in single_nb_execution
    executenb(
  File "/opt/hostedtoolcache/Python/3.10.18/x64/lib/python3.10/site-packages/nbclient/client.py", line 1319, in execute
    return NotebookClient(nb=nb, resources=resources, km=km, **kwargs).execute()
  File "/opt/hostedtoolcache/Python/3.10.18/x64/lib/python3.10/site-packages/jupyter_core/utils/__init__.py", line 165, in wrapped
    return loop.run_until_complete(inner)
  File "/opt/hostedtoolcache/Python/3.10.18/x64/lib/python3.10/asyncio/base_events.py", line 649, in run_until_complete
    return future.result()
  File "/opt/hostedtoolcache/Python/3.10.18/x64/lib/python3.10/site-packages/nbclient/client.py", line 709, in async_execute
    await self.async_execute_cell(
  File "/opt/hostedtoolcache/Python/3.10.18/x64/lib/python3.10/site-packages/nbclient/client.py", line 1062, in async_execute_cell
    await self._check_raise_for_error(cell, cell_index, exec_reply)
  File "/opt/hostedtoolcache/Python/3.10.18/x64/lib/python3.10/site-packages/nbclient/client.py", line 918, in _check_raise_for_error
    raise CellExecutionError.from_cell_and_msg(cell, exec_reply_content)
nbclient.exceptions.CellExecutionError: An error occurred while executing the following cell:
------------------
simulation_test_mean(ksample01, mu0=muK, sigma0=sigmaK)[1]
------------------


[0;31m---------------------------------------------------------------------------[0m
[0;31mTypeError[0m                                 Traceback (most recent call last)
Cell [0;32mIn[14], line 1[0m
[0;32m----> 1[0m [43msimulation_test_mean[49m[43m([49m[43mksample01[49m[43m,[49m[43m [49m[43mmu0[49m[38;5;241;43m=[39;49m[43mmuK[49m[43m,[49m[43m [49m[43msigma0[49m[38;5;241;43m=[39;49m[43msigmaK[49m[43m)[49m[43m[[49m[38;5;241;43m1[39;49m[43m][49m

[0;31mTypeError[0m: 'float' object is not subscriptable

