Traceback (most recent call last):
  File "/opt/hostedtoolcache/Python/3.10.18/x64/lib/python3.10/site-packages/jupyter_cache/executors/utils.py", line 58, in single_nb_execution
    executenb(
  File "/opt/hostedtoolcache/Python/3.10.18/x64/lib/python3.10/site-packages/nbclient/client.py", line 1319, in execute
    return NotebookClient(nb=nb, resources=resources, km=km, **kwargs).execute()
  File "/opt/hostedtoolcache/Python/3.10.18/x64/lib/python3.10/site-packages/jupyter_core/utils/__init__.py", line 165, in wrapped
    return loop.run_until_complete(inner)
  File "/opt/hostedtoolcache/Python/3.10.18/x64/lib/python3.10/asyncio/base_events.py", line 649, in run_until_complete
    return future.result()
  File "/opt/hostedtoolcache/Python/3.10.18/x64/lib/python3.10/site-packages/nbclient/client.py", line 709, in async_execute
    await self.async_execute_cell(
  File "/opt/hostedtoolcache/Python/3.10.18/x64/lib/python3.10/site-packages/nbclient/client.py", line 1062, in async_execute_cell
    await self._check_raise_for_error(cell, cell_index, exec_reply)
  File "/opt/hostedtoolcache/Python/3.10.18/x64/lib/python3.10/site-packages/nbclient/client.py", line 918, in _check_raise_for_error
    raise CellExecutionError.from_cell_and_msg(cell, exec_reply_content)
nbclient.exceptions.CellExecutionError: An error occurred while executing the following cell:
------------------
iqs = [ 82.6, 105.5,  96.7,  84.0, 127.2,  98.8,  94.3,
       122.1,  86.8,  86.1, 107.9, 118.9, 116.5, 101.0,
        91.0, 130.0, 155.7, 120.8, 107.9, 117.1, 100.1,
       108.2,  99.8, 103.6, 108.1, 110.3, 101.8, 131.7,
       103.8, 116.4]

import rpy2.robjects as robjects
from rpy2.robjects import r as runr, pandas2ri
from rpy2.robjects.packages import importr
pandas2ri.activate()

# import the BayesFactor package
BayesFactor = importr('BayesFactor')

# copy the data sample into the R workspace
robjects.globalenv["iqs"] = np.array(iqs)

# compute the Bayes factor
runr('bf = ttestBF(iqs, mu=100)')
runr('print(bf)')
------------------


[0;31m---------------------------------------------------------------------------[0m
[0;31mModuleNotFoundError[0m                       Traceback (most recent call last)
Cell [0;32mIn[23], line 7[0m
[1;32m      1[0m iqs [38;5;241m=[39m [ [38;5;241m82.6[39m, [38;5;241m105.5[39m,  [38;5;241m96.7[39m,  [38;5;241m84.0[39m, [38;5;241m127.2[39m,  [38;5;241m98.8[39m,  [38;5;241m94.3[39m,
[1;32m      2[0m        [38;5;241m122.1[39m,  [38;5;241m86.8[39m,  [38;5;241m86.1[39m, [38;5;241m107.9[39m, [38;5;241m118.9[39m, [38;5;241m116.5[39m, [38;5;241m101.0[39m,
[1;32m      3[0m         [38;5;241m91.0[39m, [38;5;241m130.0[39m, [38;5;241m155.7[39m, [38;5;241m120.8[39m, [38;5;241m107.9[39m, [38;5;241m117.1[39m, [38;5;241m100.1[39m,
[1;32m      4[0m        [38;5;241m108.2[39m,  [38;5;241m99.8[39m, [38;5;241m103.6[39m, [38;5;241m108.1[39m, [38;5;241m110.3[39m, [38;5;241m101.8[39m, [38;5;241m131.7[39m,
[1;32m      5[0m        [38;5;241m103.8[39m, [38;5;241m116.4[39m]
[0;32m----> 7[0m [38;5;28;01mimport[39;00m[38;5;250m [39m[38;5;21;01mrpy2[39;00m[38;5;21;01m.[39;00m[38;5;21;01mrobjects[39;00m[38;5;250m [39m[38;5;28;01mas[39;00m[38;5;250m [39m[38;5;21;01mrobjects[39;00m
[1;32m      8[0m [38;5;28;01mfrom[39;00m[38;5;250m [39m[38;5;21;01mrpy2[39;00m[38;5;21;01m.[39;00m[38;5;21;01mrobjects[39;00m[38;5;250m [39m[38;5;28;01mimport[39;00m r [38;5;28;01mas[39;00m runr, pandas2ri
[1;32m      9[0m [38;5;28;01mfrom[39;00m[38;5;250m [39m[38;5;21;01mrpy2[39;00m[38;5;21;01m.[39;00m[38;5;21;01mrobjects[39;00m[38;5;21;01m.[39;00m[38;5;21;01mpackages[39;00m[38;5;250m [39m[38;5;28;01mimport[39;00m importr

[0;31mModuleNotFoundError[0m: No module named 'rpy2'

