Traceback (most recent call last):
  File "/opt/hostedtoolcache/Python/3.10.18/x64/lib/python3.10/site-packages/jupyter_cache/executors/utils.py", line 58, in single_nb_execution
    executenb(
  File "/opt/hostedtoolcache/Python/3.10.18/x64/lib/python3.10/site-packages/nbclient/client.py", line 1319, in execute
    return NotebookClient(nb=nb, resources=resources, km=km, **kwargs).execute()
  File "/opt/hostedtoolcache/Python/3.10.18/x64/lib/python3.10/site-packages/jupyter_core/utils/__init__.py", line 165, in wrapped
    return loop.run_until_complete(inner)
  File "/opt/hostedtoolcache/Python/3.10.18/x64/lib/python3.10/asyncio/base_events.py", line 649, in run_until_complete
    return future.result()
  File "/opt/hostedtoolcache/Python/3.10.18/x64/lib/python3.10/site-packages/nbclient/client.py", line 709, in async_execute
    await self.async_execute_cell(
  File "/opt/hostedtoolcache/Python/3.10.18/x64/lib/python3.10/site-packages/nbclient/client.py", line 1062, in async_execute_cell
    await self._check_raise_for_error(cell, cell_index, exec_reply)
  File "/opt/hostedtoolcache/Python/3.10.18/x64/lib/python3.10/site-packages/nbclient/client.py", line 918, in _check_raise_for_error
    raise CellExecutionError.from_cell_and_msg(cell, exec_reply_content)
nbclient.exceptions.CellExecutionError: An error occurred while executing the following cell:
------------------
FH(30) - FH(10-1)
------------------


[0;31m---------------------------------------------------------------------------[0m
[0;31mAttributeError[0m                            Traceback (most recent call last)
Cell [0;32mIn[11], line 1[0m
[0;32m----> 1[0m [43mFH[49m[43m([49m[38;5;241;43m30[39;49m[43m)[49m [38;5;241m-[39m FH([38;5;241m10[39m[38;5;241m-[39m[38;5;241m1[39m)

Cell [0;32mIn[6], line 2[0m, in [0;36mFH[0;34m(b)[0m
[1;32m      1[0m [38;5;28;01mdef[39;00m[38;5;250m [39m[38;5;21mFH[39m(b):
[0;32m----> 2[0m     [38;5;28;01mreturn[39;00m [38;5;28msum[39m([fH(h) [38;5;28;01mfor[39;00m h [38;5;129;01min[39;00m [38;5;28mrange[39m([38;5;241m0[39m,b[38;5;241m+[39m[38;5;241m1[39m)])

Cell [0;32mIn[6], line 2[0m, in [0;36m<listcomp>[0;34m(.0)[0m
[1;32m      1[0m [38;5;28;01mdef[39;00m[38;5;250m [39m[38;5;21mFH[39m(b):
[0;32m----> 2[0m     [38;5;28;01mreturn[39;00m [38;5;28msum[39m([[43mfH[49m[43m([49m[43mh[49m[43m)[49m [38;5;28;01mfor[39;00m h [38;5;129;01min[39;00m [38;5;28mrange[39m([38;5;241m0[39m,b[38;5;241m+[39m[38;5;241m1[39m)])

Cell [0;32mIn[5], line 5[0m, in [0;36mfH[0;34m(h)[0m
[1;32m      3[0m [38;5;28;01mdef[39;00m[38;5;250m [39m[38;5;21mfH[39m(h):
[1;32m      4[0m     lam [38;5;241m=[39m [38;5;241m20[39m
[0;32m----> 5[0m     [38;5;28;01mreturn[39;00m lam[38;5;241m*[39m[38;5;241m*[39mh [38;5;241m*[39m np[38;5;241m.[39mexp([38;5;241m-[39mlam) [38;5;241m/[39m [43mnp[49m[38;5;241;43m.[39;49m[43mmath[49m[38;5;241m.[39mfactorial(h)

File [0;32m/opt/hostedtoolcache/Python/3.10.18/x64/lib/python3.10/site-packages/numpy/__init__.py:414[0m, in [0;36m__getattr__[0;34m(attr)[0m
[1;32m    411[0m     [38;5;28;01mimport[39;00m[38;5;250m [39m[38;5;21;01mnumpy[39;00m[38;5;21;01m.[39;00m[38;5;21;01mchar[39;00m[38;5;250m [39m[38;5;28;01mas[39;00m[38;5;250m [39m[38;5;21;01mchar[39;00m
[1;32m    412[0m     [38;5;28;01mreturn[39;00m char[38;5;241m.[39mchararray
[0;32m--> 414[0m [38;5;28;01mraise[39;00m [38;5;167;01mAttributeError[39;00m([38;5;124m"[39m[38;5;124mmodule [39m[38;5;132;01m{!r}[39;00m[38;5;124m has no attribute [39m[38;5;124m"[39m
[1;32m    415[0m                      [38;5;124m"[39m[38;5;132;01m{!r}[39;00m[38;5;124m"[39m[38;5;241m.[39mformat([38;5;18m__name__[39m, attr))

[0;31mAttributeError[0m: module 'numpy' has no attribute 'math'

